package com.warlordjones.steampunkery.gen;

import java.util.Random;

import net.minecraft.block.Block;
import net.minecraft.world.World;
import net.minecraft.world.gen.feature.WorldGenerator;

public class WorldGenAsteroid extends WorldGenerator {
    @Override
    public boolean generate(final World world, final Random par2Random,
	    final int i, final int j, final int k) {
	world.setBlock(i + 0, j + 0, k + 0, Block.stoneBrick.blockID);
	world.setBlock(i + 0, j + 0, k + 1, Block.stoneBrick.blockID);
	world.setBlock(i + 0, j + 0, k + 2, Block.stoneBrick.blockID);
	world.setBlock(i + 0, j + 0, k + 3, Block.stoneBrick.blockID);
	world.setBlock(i + 0, j + 0, k + 4, Block.stoneBrick.blockID);
	world.setBlock(i + 0, j + 1, k + 0, Block.stoneBrick.blockID);
	world.setBlock(i + 0, j + 1, k + 1, Block.stoneBrick.blockID);
	world.setBlock(i + 0, j + 1, k + 3, Block.stoneBrick.blockID);
	world.setBlock(i + 0, j + 1, k + 4, Block.stoneBrick.blockID);
	world.setBlock(i + 0, j + 2, k + 0, Block.stoneBrick.blockID);
	world.setBlock(i + 0, j + 2, k + 1, Block.stoneBrick.blockID);
	world.setBlock(i + 0, j + 2, k + 3, Block.stoneBrick.blockID);
	world.setBlock(i + 0, j + 2, k + 4, Block.stoneBrick.blockID);
	world.setBlock(i + 0, j + 3, k + 0, Block.stoneBrick.blockID);
	world.setBlock(i + 0, j + 3, k + 1, Block.stoneBrick.blockID);
	world.setBlock(i + 0, j + 3, k + 2, Block.stoneBrick.blockID);
	world.setBlock(i + 0, j + 3, k + 3, Block.stoneBrick.blockID);
	world.setBlock(i + 0, j + 3, k + 4, Block.stoneBrick.blockID);
	world.setBlock(i + 1, j + 0, k + 0, Block.stoneBrick.blockID);
	world.setBlock(i + 1, j + 0, k + 1, Block.stoneBrick.blockID);
	world.setBlock(i + 1, j + 0, k + 2, Block.stoneBrick.blockID);
	world.setBlock(i + 1, j + 0, k + 3, Block.stoneBrick.blockID);
	world.setBlock(i + 1, j + 0, k + 4, Block.stoneBrick.blockID);
	world.setBlock(i + 1, j + 1, k + 0, Block.stoneBrick.blockID);
	world.setBlock(i + 1, j + 1, k + 4, Block.stoneBrick.blockID);
	world.setBlock(i + 1, j + 2, k + 0, Block.stoneBrick.blockID);
	world.setBlock(i + 1, j + 2, k + 4, Block.stoneBrick.blockID);
	world.setBlock(i + 1, j + 3, k + 0, Block.stoneBrick.blockID);
	world.setBlock(i + 1, j + 3, k + 1, Block.stoneBrick.blockID);
	world.setBlock(i + 1, j + 3, k + 2, Block.stoneBrick.blockID);
	world.setBlock(i + 1, j + 3, k + 3, Block.stoneBrick.blockID);
	world.setBlock(i + 1, j + 3, k + 4, Block.stoneBrick.blockID);
	world.setBlock(i + 2, j + 0, k + 0, Block.stoneBrick.blockID);
	world.setBlock(i + 2, j + 0, k + 1, Block.stoneBrick.blockID);
	world.setBlock(i + 2, j + 0, k + 2, Block.stoneBrick.blockID);
	world.setBlock(i + 2, j + 0, k + 3, Block.stoneBrick.blockID);
	world.setBlock(i + 2, j + 0, k + 4, Block.stoneBrick.blockID);
	world.setBlock(i + 2, j + 1, k + 0, Block.stoneBrick.blockID);
	world.setBlock(i + 2, j + 1, k + 4, Block.stoneBrick.blockID);
	world.setBlock(i + 2, j + 2, k + 0, Block.stoneBrick.blockID);
	world.setBlock(i + 2, j + 2, k + 4, Block.stoneBrick.blockID);
	world.setBlock(i + 2, j + 3, k + 0, Block.stoneBrick.blockID);
	world.setBlock(i + 2, j + 3, k + 1, Block.stoneBrick.blockID);
	world.setBlock(i + 2, j + 3, k + 2, Block.stoneBrick.blockID);
	world.setBlock(i + 2, j + 3, k + 3, Block.stoneBrick.blockID);
	world.setBlock(i + 2, j + 3, k + 4, Block.stoneBrick.blockID);
	world.setBlock(i + 3, j + 0, k + 0, Block.stoneBrick.blockID);
	world.setBlock(i + 3, j + 0, k + 1, Block.stoneBrick.blockID);
	world.setBlock(i + 3, j + 0, k + 2, Block.stoneBrick.blockID);
	world.setBlock(i + 3, j + 0, k + 3, Block.stoneBrick.blockID);
	world.setBlock(i + 3, j + 0, k + 4, Block.stoneBrick.blockID);
	world.setBlock(i + 3, j + 1, k + 0, Block.stoneBrick.blockID);
	world.setBlock(i + 3, j + 1, k + 4, Block.stoneBrick.blockID);
	world.setBlock(i + 3, j + 2, k + 0, Block.stoneBrick.blockID);
	world.setBlock(i + 3, j + 2, k + 4, Block.stoneBrick.blockID);
	world.setBlock(i + 3, j + 3, k + 0, Block.stoneBrick.blockID);
	world.setBlock(i + 3, j + 3, k + 1, Block.stoneBrick.blockID);
	world.setBlock(i + 3, j + 3, k + 2, Block.stoneBrick.blockID);
	world.setBlock(i + 3, j + 3, k + 3, Block.stoneBrick.blockID);
	world.setBlock(i + 3, j + 3, k + 4, Block.stoneBrick.blockID);
	world.setBlock(i + 4, j + 0, k + 0, Block.stoneBrick.blockID);
	world.setBlock(i + 4, j + 0, k + 1, Block.stoneBrick.blockID);
	world.setBlock(i + 4, j + 0, k + 2, Block.stoneBrick.blockID);
	world.setBlock(i + 4, j + 0, k + 3, Block.stoneBrick.blockID);
	world.setBlock(i + 4, j + 0, k + 4, Block.stoneBrick.blockID);
	world.setBlock(i + 4, j + 1, k + 0, Block.stoneBrick.blockID);
	world.setBlock(i + 4, j + 1, k + 1, Block.stoneBrick.blockID);
	world.setBlock(i + 4, j + 1, k + 2, Block.stoneBrick.blockID);
	world.setBlock(i + 4, j + 1, k + 3, Block.stoneBrick.blockID);
	world.setBlock(i + 4, j + 1, k + 4, Block.stoneBrick.blockID);
	world.setBlock(i + 4, j + 2, k + 0, Block.stoneBrick.blockID);
	world.setBlock(i + 4, j + 2, k + 1, Block.fenceIron.blockID);
	world.setBlock(i + 4, j + 2, k + 2, Block.fenceIron.blockID);
	world.setBlock(i + 4, j + 2, k + 3, Block.fenceIron.blockID);
	world.setBlock(i + 4, j + 2, k + 4, Block.stoneBrick.blockID);
	world.setBlock(i + 4, j + 3, k + 0, Block.stoneBrick.blockID);
	world.setBlock(i + 4, j + 3, k + 1, Block.stoneBrick.blockID);
	world.setBlock(i + 4, j + 3, k + 2, Block.stoneBrick.blockID);
	world.setBlock(i + 4, j + 3, k + 3, Block.stoneBrick.blockID);
	world.setBlock(i + 4, j + 3, k + 4, Block.stoneBrick.blockID);
	world.setBlock(i + 3, j + 2, k + 1, Block.torchWood.blockID);
	return true;
    }
}
